Workbook

Sheet 見積内訳
A1: 御 見 積 内 訳 書
A3: 工 事 名 | B3: 車寄せ 前方・後方パネル／ルーバー 撤去工事（仮称）
A4: 工事場所 | B4: 神奈川県横浜市都筑区茅ケ崎南 3-23-5 信和ホームズ㈱ 社屋 車寄せ
A5: 現地調査 | B5: 2026年9月2日（水）9:00 立会：専務 藤井 様（熊谷組 担当）／社長 古谷 様／会長 園尾 様
A6: 工事概要 | B6: 前方パネル（ケイカル板）一部4面 ／ 後方パネル 1面 ／ 奥のルーバー＋下地（鉄骨アングル）の撤去。取合い部シールは先行撤去。撤去後は鉄骨あらわし。
A7: 施工条件 | B7: 道路側：高所作業車 ／ 敷地内：ローリングタワー ／ 営業中（駐車車両の移動・養生あり）
A8: 作成日 | B8: 2026年9月2日 （数量根拠：別シート「数量根拠」）
A10: 【記入方法】黄色セル（F列 単価）に単価を入力すると金額（G列）が自動計算されます。数量（D列）は「数量根拠」シートと連動。
A11: No. | B11: 工種・項目 | C11: 仕様・摘要 | D11: 数量 | E11: 単位 | F11: 単価 | G11: 金額 | H11: 備考
B12: Ⅰ．仮設工事
A13: 1 | B13: 現場仮設・養生 | C13: 作業区画、周辺養生、看板・カラーコーン等 | D13: 1 | E13: 式 | G13: =IF(F13="","",D13*F13) | H13: 駐車場・歩道の養生共
A14: 2 | B14: 高所作業車（道路側） | C14: スカイマスター等 賃料・回送費 | D14: 2 | E14: 日 | G14: =IF(F14="","",D14*F14) | H14: ※稼働日数は施工計画により調整
A15: 3 | B15: ローリングタワー（敷地内） | C15: 組立・解体・移動・賃料 | D15: 1 | E15: 式 | G15: =IF(F15="","",D15*F15) | H15: 敷地内はローリングにて施工
A16: 4 | B16: 道路使用許可申請・歩道養生 | C16: 警察届出、歩行者誘導員共 | D16: 1 | E16: 式 | G16: =IF(F16="","",D16*F16) | H16: 要否は道路管理者と協議
A17: 5 | B17: 駐車車両の移動・場内調整 | C17: 営業中のため作業前後の車両移動 | D17: 1 | E17: 式 | G17: =IF(F17="","",D17*F17)
B18: Ⅱ．事前調査（石綿）
A19: 6 | B19: 石綿事前調査 | C19: 有資格者による調査・報告（労基署／自治体届出共） | D19: 1 | E19: 式 | G19: =IF(F19="","",D19*F19) | H19: 法定（改正大防法・安衛法）
A20: 7 | B20: 石綿分析（定性分析） | C20: ケイカル板・シール材・その他仕上材 | D20: 3 | E20: 検体 | G20: =IF(F20="","",D20*F20) | H20: 検体数は調査結果による
B21: Ⅲ．撤去工事
A22: 8 | B22: 取合い部シール 先行撤去 | C22: 既存シーリング（変成シリコーン等） 本体撤去に先行 | D22: =数量根拠!C31 | E22: m | G22: =IF(F22="","",D22*F22) | H22: 石綿含有時は湿潤化・作業計画別途
A23: 9 | B23: 前方パネル 撤去 | C23: ケイカル板（サイン付き上部梁 前面） 一部4面 H=1.0m | D23: =数量根拠!C26 | E23: ㎡ | G23: =IF(F23="","",D23*F23) | H23: 道路側：高所作業車にて施工
A24: 10 | B24: 前方パネル 下部見切り 撤去 | C24: 下部 300 の見切り・板金部 | D24: =数量根拠!C27 | E24: m | G24: =IF(F24="","",D24*F24) | H24: パネルと一体の場合は No.9 に含む
A25: 11 | B25: 後方パネル 撤去 | C25: ケイカル板（中段梁・屋根と一体） 1面 | D25: =数量根拠!C28 | E25: ㎡ | G25: =IF(F25="","",D25*F25) | H25: 敷地内：ローリングタワーにて施工
A26: 12 | B26: ルーバー 撤去 | C26: アルミ／鋼製ルーバー 奥のルーバー部 | D26: =数量根拠!C29 | E26: ㎡ | G26: =IF(F26="","",D26*F26) | H26: 5.8m × 4.8m（幅は要確認）
A27: 13 | B27: ルーバー下地 撤去 | C27: 鉄骨アングル下地（母屋・振れ止め共） | D27: =数量根拠!C30 | E27: ㎡ | G27: =IF(F27="","",D27*F27) | H27: 溶断・ボルト外し共
A28: 14 | B28: 撤去材 小運搬・積込 | C28: 場内小運搬、荷降ろし、積込手間 | D28: 1 | E28: 式 | G28: =IF(F28="","",D28*F28)
A29: 15 | B29: 清掃・後片付け | C29: 作業後の清掃、車路の復旧 | D29: 1 | E29: 式 | G29: =IF(F29="","",D29*F29)
B30: Ⅳ．運搬・処分
A31: 16 | B31: 廃材運搬 | C31: 4t 車 現場 → 処分場 | D31: 2 | E31: 台 | G31: =IF(F31="","",D31*F31) | H31: 積載量により調整
A32: 17 | B32: 処分費（金属くず） | C32: ルーバー・鉄骨アングル・板金 | D32: 1.5 | E32: t | G32: =IF(F32="","",D32*F32) | H32: 有価物となる場合は控除
A33: 18 | B33: 処分費（ケイカル板・混合廃棄物） | C33: 石綿非含有の場合 | D33: 2 | E33: ㎥ | G33: =IF(F33="","",D33*F33) | H33: 分析結果により区分
A34: 19 | B34: 処分費（石綿含有廃棄物） | C34: レベル3該当時（ケイカル板・シール材） | D34: 0 | E34: kg | G34: =IF(F34="","",D34*F34) | H34: ※分析で含有判明時に別途計上
B35: Ⅴ．諸経費
A36: 20 | B36: 現場管理費・安全衛生費 | C36: 有資格者配置、KY・安全書類、保護具 | D36: 1 | E36: 式 | G36: =IF(F36="","",D36*F36)
A37: 21 | B37: 諸経費 | C37: 一般管理費等 | D37: 1 | E37: 式 | G37: =IF(F37="","",D37*F37) | H37: 下記 率入力でも可
B39: 直接工事費 計（Ⅰ〜Ⅴ） | G39: =SUM(G12:G37)
B40: 値引き | G40: =IF(F40="",0,-F40) | H40: ※値引額を黄色セルに正数で入力
B41: 小 計 | G41: =G39+G40
B42: 消費税 | D42: 0.1 | E42: 率 | G42: =ROUND(G41*D42,0)
B43: 合 計（税込） | G43: =G41+G42
...

Sheet 数量根拠
A1: 数量根拠（2026/09/02 現地調査 実測値）
A2: 出典：現地調査時の書込み図面（撤去範囲図 図番01 rev.4 への赤・青書込み PDF）。青字＝実測値・聞取り、黒字＝計算式。
A4: ■ 実測値（書込みより）
A5: 記号 | B5: 項目 | C5: 値 | D5: 単位 | E5: 記載箇所・備考
A6: m1 | B6: A 前方パネル 全長 | C6: 19.5 | D6: m | E6: 正面図 L1 赤書き 19.5m
A7: m2 | B7: A 前方パネル 高さ | C7: 1 | D7: m | E7: 正面図 赤書き 1000
A8: m3 | B8: A 前方パネル 下部見切り | C8: 0.3 | D8: m | E8: 上空図 赤書き 300（下部）
A9: m4 | B9: B 後方パネル 全長 | C9: 14 | D9: m | E9: 正面図 L2 赤書き 14m
A10: m5 | B10: B 後方パネル 高さ（仮定） | C10: 1 | D10: m | E10: ※未測定。A と同等と仮定 → 要確認
A11: m6 | B11: 前面帯（波板・CON・吹抜け）奥行 | C11: 2.1 | D11: m | E11: 上空図 赤書き 2100
A12: m7 | B12: 右端部（吹抜け側）幅 | C12: 4.8 | D12: m | E12: 上空図 赤書き 4800
A13: m8 | B13: ルーバー部 奥行 | C13: 5.8 | D13: m | E13: 上空図 赤書き 5800（赤の切断位置マーク間）
A14: m9 | B14: ルーバー部 幅（仮定） | C14: 4.8 | D14: m | E14: ※未測定。m7（吹抜け部幅）と同幅と仮定 → 要確認
A16: ■ 仕様（聞取り・書込み）
A17: s1 | B17: パネル材質 | C17: ケイカル板 | D17: － | E17: 工事概要欄 青書き「鉄骨あらわし、ケイカル 15ヶ …」
A18: s2 | B18: パネル数量（聞取り） | C18: 15 ヶ | D18: － | E18: 「ケイカル 15ヶ」＝枚数か箇所数か要確認
A19: s3 | B19: 下地 | C19: 鉄骨アングル | D19: － | E19: 上空図 青書き「鉄骨アングル」
A20: s4 | B20: 撤去後の状態 | C20: 鉄骨あらわし | D20: － | E20: 仕上げ復旧の要否は別途確認
A21: s5 | B21: 前面帯 左側の屋根材 | C21: ポリカ波板 | D21: － | E21: 上空図 青書き「ポリカ」。撤去範囲外（別途）
A23: ■ 数量計算
A24: 記号 | B24: 項目 | C24: 数量 | D24: 単位 | E24: 計算式
A25: Q1 | B25: A 前方パネル 撤去面積 | C25: =C6*C7 | D25: ㎡ | E25: m1 × m2 ＝ 19.5m × 1.0m
A26: Q2 | B26: A 前方パネル 下部見切り 撤去 | C26: =C6 | D26: m | E26: m1（下部300 の見切り材・延長）
A27: Q3 | B27: B 後方パネル 撤去面積 | C27: =C9*C10 | D27: ㎡ | E27: m4 × m5 ＝ 14.0m × 1.0m（高さ仮定）
A28: Q4 | B28: ルーバー 撤去面積 | C28: =C13*C14 | D28: ㎡ | E28: m8 × m9 ＝ 5.8m × 4.8m（幅は仮定）
A29: Q5 | B29: ルーバー下地（鉄骨アングル）撤去 | C29: =C13*C14 | D29: ㎡ | E29: Q4 と同数量
A30: Q6 | B30: 取合い部シール 先行撤去 延長 | C30: =(C6+C7)*2+(C9+C10)*2 | D30: m | E30: A・B パネル外周の目地（概算）→ 要確認
A31: Q7 | B31: 撤去材 合計（概算） | C31: =C26+C28+C29 | D31: ㎡ | E31: Q1＋Q3＋Q4（面積計）
A33: ※ 青字は現地実測値・聞取り。黒字はそれを用いた計算値。仮定値（m5・m9）は現地確認後に上書きすると見積内訳の数量・金額が自動で更新されます。
